I'm sorry, but an uncaught exception occurred.

While running game code:
  File "game/script.rpy", line 89, in script
    python:
  File "game/script.rpy", line 108, in <module>
    turn_step_reset()
  File "game/gameplay/global_variables.rpy", line 42, in turn_step_reset
    each.player_turn_end()
  File "game/gameplay/Player.rpy", line 336, in player_turn_end
    
NameError: global name 'agents_at_turn' is not defined

-- Full Traceback ------------------------------------------------------------

Full traceback:
  File "game/script.rpy", line 89, in script
    python:
  File "C:\Users\Michael\Desktop\Renpy\renpy-7.3.5-sdk\renpy\ast.py", line 914, in execute
    renpy.python.py_exec_bytecode(self.code.bytecode, self.hide, store=self.store)
  File "C:\Users\Michael\Desktop\Renpy\renpy-7.3.5-sdk\renpy\python.py", line 2028, in py_exec_bytecode
    exec bytecode in globals, locals
  File "game/script.rpy", line 108, in <module>
    turn_step_reset()
  File "game/gameplay/global_variables.rpy", line 42, in turn_step_reset
    each.player_turn_end()
  File "game/gameplay/Player.rpy", line 336, in player_turn_end
    
NameError: global name 'agents_at_turn' is not defined

Windows-8-6.2.9200
Ren'Py 7.3.5.606
Tricks and Treats 1.0
Mon Oct 26 15:08:00 2020
